
local _ = {name = "air", param1 = 0}
local t = {name = "ethereal:banana_trunk", param1 = 255}
local T = {name = "ethereal:banana_trunk", param1 = 255, force_place = true}
local L = {name = "ethereal:bananaleaves", param1 = 255}
local l = {name = "ethereal:bananaleaves", param1 = 180}
local B = {name = "ethereal:banana", param1 = 255}
local b = {name = "ethereal:banana", param1 = 070}

ethereal.bananatree = {

	size = {x = 7, y = 8, z = 7},

	yslice_prob = {
		{ypos = 2, prob = 127},
		{ypos = 3, prob = 127}
	},

	data = {

	_,_,_,_,_,_,_,
	_,_,_,_,_,_,_,
	_,_,_,_,_,_,_,
	_,_,_,_,_,_,_,
	_,_,_,_,_,_,_,
	_,_,_,_,_,_,_,
	_,_,_,_,_,_,_,
	_,_,_,l,_,_,_,

	_,_,_,_,_,_,_,
	_,_,_,_,_,_,_,
	_,_,_,_,_,_,_,
	_,_,_,_,_,_,_,
	_,_,_,_,_,_,_,
	_,_,_,_,_,_,_,
	_,_,_,l,_,_,_,
	_,_,_,L,_,_,_,

	_,_,_,_,_,_,_,
	_,_,_,_,_,_,_,
	_,_,_,_,_,_,_,
	_,_,_,_,_,_,_,
	_,_,_,b,_,_,_,
	_,_,_,B,_,_,_,
	_,_,_,L,_,_,_,
	_,_,_,_,_,_,_,

	_,_,_,T,_,_,_,
	_,_,_,T,_,_,_,
	_,_,_,T,_,_,_,
	_,_,_,T,_,_,_,
	_,_,b,t,b,_,_,
	_,_,B,t,B,_,_,
	_,L,L,L,L,L,_,
	l,l,_,L,_,l,l,

	_,_,_,_,_,_,_,
	_,_,_,_,_,_,_,
	_,_,_,_,_,_,_,
	_,_,_,_,_,_,_,
	_,_,_,b,_,_,_,
	_,_,_,B,_,_,_,
	_,_,_,L,_,_,_,
	_,_,_,_,_,_,_,

	_,_,_,_,_,_,_,
	_,_,_,_,_,_,_,
	_,_,_,_,_,_,_,
	_,_,_,_,_,_,_,
	_,_,_,_,_,_,_,
	_,_,_,_,_,_,_,
	_,_,_,L,_,_,_,
	_,_,_,l,_,_,_,

	_,_,_,_,_,_,_,
	_,_,_,_,_,_,_,
	_,_,_,_,_,_,_,
	_,_,_,_,_,_,_,
	_,_,_,_,_,_,_,
	_,_,_,_,_,_,_,
	_,_,_,_,_,_,_,
	_,_,_,l,_,_,_,

	}
}
