
local _ = {name = "air", prob = 0}
local t = {name = "ethereal:redwood_trunk", prob = 255}
local T = {name = "ethereal:redwood_trunk", prob = 255, force_place = true}
local L = {name = "ethereal:redwood_leaves", prob = 255}

ethereal.redwood_tree = {

	size = {x = 15, y = 33, z = 15},

	yslice_prob = {
		{ypos = 1, prob = 127},
		{ypos = 5, prob = 127},
		{ypos = 6, prob = 127},
		{ypos = 7, prob = 127},
		{ypos = 14, prob = 127},
		{ypos = 15, prob = 127},
		{ypos = 16, prob = 127}
	},

	data = {

	_,_,_,_,_,_,_,_,_,_,_,_,_,_,_,
	_,_,_,_,_,_,_,_,_,_,_,_,_,_,_,
	_,_,_,_,_,_,_,_,_,_,_,_,_,_,_,
	_,_,_,_,_,_,_,_,_,_,_,_,_,_,_,
	_,_,_,_,_,_,_,_,_,_,_,_,_,_,_,
	_,_,_,_,_,_,_,_,_,_,_,_,_,_,_,
	_,_,_,_,_,_,_,_,_,_,_,_,_,_,_,
	_,_,_,_,_,_,_,_,_,_,_,_,_,_,_,
	_,_,_,_,_,_,_,_,_,_,_,_,_,_,_,
	_,_,_,_,_,_,_,_,_,_,_,_,_,_,_,
	_,_,_,_,_,_,_,_,_,_,_,_,_,_,_,
	_,_,_,_,_,_,_,_,_,_,_,_,_,_,_,
	_,_,_,_,_,_,_,_,_,_,_,_,_,_,_,
	_,_,_,_,_,_,_,_,_,_,_,_,_,_,_,
	_,_,_,_,_,_,_,_,_,_,_,_,_,_,_,
	_,_,_,_,_,_,_,_,_,_,_,_,_,_,_,
	_,_,_,_,_,_,_,_,_,_,_,_,_,_,_,
	_,_,_,_,_,_,_,_,_,_,_,_,_,_,_,
	_,_,_,_,_,L,L,L,L,L,_,_,_,_,_,
	_,_,_,_,_,_,L,L,L,_,_,_,_,_,_,
	_,_,_,_,_,_,_,_,_,_,_,_,_,_,_,
	_,_,_,_,_,_,_,_,_,_,_,_,_,_,_,
	_,_,_,_,_,_,_,_,_,_,_,_,_,_,_,
	_,_,_,_,_,_,_,_,_,_,_,_,_,_,_,
	_,_,_,_,_,_,_,_,_,_,_,_,_,_,_,
	_,_,_,_,_,_,_,_,_,_,_,_,_,_,_,
	_,_,_,_,_,_,_,_,_,_,_,_,_,_,_,
	_,_,_,_,_,_,_,_,_,_,_,_,_,_,_,
	_,_,_,_,_,_,_,_,_,_,_,_,_,_,_,
	_,_,_,_,_,_,_,_,_,_,_,_,_,_,_,
	_,_,_,_,_,_,_,_,_,_,_,_,_,_,_,
	_,_,_,_,_,_,_,_,_,_,_,_,_,_,_,
	_,_,_,_,_,_,_,_,_,_,_,_,_,_,_,

	_,_,_,_,_,_,_,_,_,_,_,_,_,_,_,
	_,_,_,_,_,_,_,_,_,_,_,_,_,_,_,
	_,_,_,_,_,_,_,_,_,_,_,_,_,_,_,
	_,_,_,_,_,_,_,_,_,_,_,_,_,_,_,
	_,_,_,_,_,_,_,_,_,_,_,_,_,_,_,
	_,_,_,_,_,_,_,_,_,_,_,_,_,_,_,
	_,_,_,_,_,_,_,_,_,_,_,_,_,_,_,
	_,_,_,_,_,_,_,_,_,_,_,_,_,_,_,
	_,_,_,_,_,_,_,_,_,_,_,_,_,_,_,
	_,_,_,_,_,_,_,_,_,_,_,_,_,_,_,
	_,_,_,_,_,_,_,_,_,_,_,_,_,_,_,
	_,_,_,_,_,_,_,_,_,_,_,_,_,_,_,
	_,_,_,_,_,_,_,_,_,_,_,_,_,_,_,
	_,_,_,_,_,_,_,_,_,_,_,_,_,_,_,
	_,_,_,_,_,_,_,_,_,_,_,_,_,_,_,
	_,_,_,_,_,_,_,_,_,_,_,_,_,_,_,
	_,_,_,_,_,_,_,_,_,_,_,_,_,_,_,
	_,_,_,_,_,L,L,_,L,_,_,_,_,_,_,
	_,_,_,_,L,L,L,t,L,L,_,_,_,_,_,
	_,_,_,_,_,L,L,L,L,_,_,_,_,_,_,
	_,_,_,_,_,_,_,_,_,_,_,_,_,_,_,
	_,_,_,_,_,_,_,_,_,_,_,_,_,_,_,
	_,_,_,_,_,_,_,_,_,_,_,_,_,_,_,
	_,_,_,_,_,_,_,_,L,L,L,_,_,_,_,
	_,_,_,_,_,_,_,_,_,_,_,_,_,_,_,
	_,_,_,_,_,_,_,_,_,_,_,_,_,_,_,
	_,_,_,_,_,_,_,_,_,_,_,_,_,_,_,
	_,_,_,_,_,_,_,_,_,_,_,_,_,_,_,
	_,_,_,_,_,_,_,_,_,_,_,_,_,_,_,
	_,_,_,_,_,_,_,_,_,_,_,_,_,_,_,
	_,_,_,_,_,_,_,_,_,_,_,_,_,_,_,
	_,_,_,_,_,_,_,_,_,_,_,_,_,_,_,
	_,_,_,_,_,_,_,_,_,_,_,_,_,_,_,

	_,_,_,_,_,_,_,_,_,_,_,_,_,_,_,
	_,_,_,_,_,_,_,_,_,_,_,_,_,_,_,
	_,_,_,_,_,_,_,_,_,_,_,_,_,_,_,
	_,_,_,_,_,_,_,_,_,_,_,_,_,_,_,
	_,_,_,_,_,_,_,_,_,_,_,_,_,_,_,
	_,_,_,_,_,_,_,_,_,_,_,_,_,_,_,
	_,_,_,_,_,_,_,_,_,_,_,_,_,_,_,
	_,_,_,_,_,_,_,_,_,_,_,_,_,_,_,
	_,_,_,_,_,_,_,_,_,_,_,_,_,_,_,
	_,_,_,_,_,_,_,_,_,_,_,_,_,_,_,
	_,_,_,_,_,_,_,_,_,_,_,_,_,_,_,
	_,_,_,_,_,_,_,_,_,_,_,_,_,_,_,
	_,_,_,_,_,_,_,_,_,_,_,_,_,_,_,
	_,_,_,_,_,_,_,_,_,_,_,_,_,_,_,
	_,_,_,_,_,_,_,_,_,_,_,_,_,_,_,
	_,_,_,_,_,_,_,_,_,_,_,_,_,_,_,
	_,_,_,_,_,_,_,_,_,_,_,_,_,_,_,
	_,_,_,_,_,L,L,t,L,L,_,_,_,_,_,
	_,_,_,_,L,L,L,t,L,L,_,_,_,_,_,
	_,_,_,_,_,L,L,L,L,_,_,_,_,_,_,
	_,_,_,_,_,_,_,_,_,_,_,_,_,_,_,
	_,_,_,_,_,_,_,_,_,_,_,_,_,_,_,
	_,_,_,_,_,_,_,_,_,_,_,_,_,_,_,
	_,_,_,_,_,_,_,L,L,L,L,L,_,_,_,
	_,_,_,_,_,_,_,_,L,L,L,_,_,_,_,
	_,_,_,_,_,_,_,_,_,_,_,_,_,_,_,
	_,_,_,_,_,_,_,_,_,_,_,_,_,_,_,
	_,_,_,_,_,_,_,_,_,_,_,_,_,_,_,
	_,_,_,_,_,_,_,_,_,_,_,_,_,_,_,
	_,_,_,_,_,_,_,_,_,_,_,_,_,_,_,
	_,_,_,_,_,_,_,_,_,_,_,_,_,_,_,
	_,_,_,_,_,_,_,_,_,_,_,_,_,_,_,
	_,_,_,_,_,_,_,_,_,_,_,_,_,_,_,

	_,_,_,_,_,_,_,_,_,_,_,_,_,_,_,
	_,_,_,_,_,_,_,_,_,_,_,_,_,_,_,
	_,_,_,_,_,_,_,_,_,_,_,_,_,_,_,
	_,_,_,_,_,_,_,_,_,_,_,_,_,_,_,
	_,_,_,_,_,_,_,_,_,_,_,_,_,_,_,
	_,_,_,_,_,_,_,_,_,_,_,_,_,_,_,
	_,_,_,_,_,_,_,_,_,_,_,_,_,_,_,
	_,_,_,_,_,_,_,_,_,_,_,_,_,_,_,
	_,_,_,_,_,_,_,_,_,_,_,_,_,_,_,
	_,_,_,_,_,_,_,_,_,_,_,_,_,_,_,
	_,_,_,_,_,_,_,_,_,_,_,_,_,_,_,
	_,_,_,_,_,_,_,_,_,_,_,_,_,_,_,
	_,_,_,_,_,_,_,_,_,_,_,_,_,_,_,
	_,_,_,_,_,_,_,_,_,_,_,_,_,_,_,
	_,_,_,_,_,_,_,_,_,_,_,_,_,_,_,
	_,_,_,_,_,_,_,_,_,_,_,_,_,_,_,
	_,_,_,_,_,_,_,_,_,_,_,_,_,_,_,
	_,_,_,_,_,L,L,t,L,L,_,_,_,_,_,
	_,_,_,_,_,L,L,L,L,_,_,_,_,_,_,
	_,_,_,_,_,_,_,L,_,_,_,_,_,_,_,
	_,_,_,_,_,_,_,_,_,_,_,_,_,_,_,
	_,_,_,_,_,_,_,_,_,_,_,_,_,_,_,
	_,_,_,_,_,_,_,_,_,_,_,_,_,_,_,
	_,_,_,_,_,_,_,L,L,t,L,L,_,_,_,
	_,_,_,_,_,_,_,_,L,L,L,_,_,_,_,
	_,_,_,_,_,_,_,_,_,_,_,_,_,_,_,
	_,_,_,_,L,L,L,L,_,_,_,_,_,_,_,
	_,_,_,_,_,_,_,_,_,_,_,_,_,_,_,
	_,_,_,_,_,_,_,_,_,_,_,_,_,_,_,
	_,_,_,_,_,_,L,L,_,_,_,_,_,_,_,
	_,_,_,_,_,_,_,_,_,_,_,_,_,_,_,
	_,_,_,_,_,_,_,_,_,_,_,_,_,_,_,
	_,_,_,_,_,_,_,_,_,_,_,_,_,_,_,

	_,_,_,_,_,T,T,T,T,T,_,_,_,_,_,
	_,_,_,_,_,_,T,T,_,_,_,_,_,_,_,
	_,_,_,_,_,_,_,_,_,_,_,_,_,_,_,
	_,_,_,_,_,_,_,_,_,_,_,_,_,_,_,
	_,_,_,_,_,_,_,_,_,_,_,_,_,_,_,
	_,_,_,_,_,_,_,_,_,_,_,_,_,_,_,
	_,_,_,_,_,_,_,_,_,_,_,_,_,_,_,
	_,_,_,_,_,_,_,_,_,_,_,_,_,_,_,
	_,_,_,_,_,_,_,_,_,_,_,_,_,_,_,
	_,_,_,_,_,_,_,_,_,_,_,_,_,_,_,
	_,_,_,_,_,_,_,_,_,_,_,_,_,_,_,
	_,_,_,_,_,_,_,_,_,_,_,_,_,_,_,
	_,_,_,_,_,_,_,_,_,_,_,_,_,_,_,
	_,_,_,_,_,_,_,_,_,_,_,_,_,_,_,
	_,_,_,_,_,_,_,_,_,_,_,_,_,_,_,
	_,_,_,_,_,_,_,_,_,_,_,_,_,_,_,
	_,_,_,_,_,_,_,_,_,_,_,_,_,_,_,
	_,_,_,_,_,_,L,t,L,L,_,_,_,_,_,
	_,_,_,_,_,_,L,L,_,_,_,_,_,_,_,
	_,_,_,_,_,_,_,_,_,_,_,_,_,_,_,
	_,_,_,_,_,_,_,_,_,_,_,_,_,_,_,
	_,_,_,_,_,_,_,_,_,_,_,_,_,_,_,
	_,_,_,_,_,_,_,_,_,t,_,_,_,_,_,
	_,_,_,_,_,_,_,L,L,t,L,L,_,_,_,
	_,_,_,_,_,_,_,_,L,L,L,_,_,_,_,
	_,_,_,_,_,_,_,_,_,_,_,_,_,_,_,
	_,_,_,L,L,L,L,L,L,_,_,_,_,_,_,
	_,_,_,_,_,L,L,_,_,_,_,_,_,_,_,
	_,_,_,_,_,_,_,_,_,_,_,_,_,_,_,
	_,_,_,_,_,_,L,L,L,L,_,_,_,_,_,
	_,_,_,_,_,_,L,L,L,_,_,_,_,_,_,
	_,_,_,_,_,_,_,_,_,_,_,_,_,_,_,
	_,_,_,_,_,_,_,_,_,_,_,_,_,_,_,

	_,_,_,_,_,T,T,T,T,T,_,_,_,_,_,
	_,_,_,_,_,T,T,T,T,T,_,_,_,_,_,
	_,_,_,_,_,_,T,T,T,_,_,_,_,_,_,
	_,_,_,_,_,_,T,T,T,_,_,_,_,_,_,
	_,_,_,_,_,_,t,t,t,_,_,_,_,_,_,
	_,_,_,_,_,_,t,t,t,_,_,_,_,_,_,
	_,_,_,_,_,_,t,t,t,_,_,_,_,_,_,
	_,_,_,_,_,_,t,t,t,_,_,_,_,_,_,
	_,_,_,_,_,_,t,t,t,_,_,_,_,_,_,
	_,_,_,_,_,_,_,t,_,_,_,_,_,_,_,
	_,_,_,_,_,_,_,t,_,_,_,_,_,_,_,
	_,_,_,_,_,_,_,t,_,_,_,_,_,_,_,
	_,_,_,_,_,_,_,_,_,_,_,_,_,_,_,
	_,_,_,_,_,_,_,_,_,_,_,_,_,_,_,
	_,_,_,_,_,_,_,_,_,_,_,_,_,_,_,
	_,_,_,_,_,_,_,_,_,_,_,_,_,_,_,
	_,_,_,_,_,_,_,_,_,_,_,_,_,_,_,
	_,_,_,_,_,_,_,t,_,_,_,_,_,_,_,
	_,_,_,_,_,_,_,_,_,_,_,_,_,_,_,
	_,_,_,_,_,_,_,_,_,_,_,_,_,_,_,
	_,_,_,_,_,_,_,_,_,_,_,_,_,_,_,
	_,_,_,_,_,_,_,_,_,_,_,_,_,_,_,
	_,_,_,_,_,_,_,_,t,t,_,_,_,_,_,
	_,_,_,_,_,_,_,_,L,L,_,L,L,L,L,
	_,_,_,_,_,_,_,_,_,_,_,_,_,_,_,
	_,_,_,_,_,_,_,_,_,_,_,_,_,_,_,
	_,_,_,L,L,t,t,L,L,_,_,_,_,_,_,
	_,_,_,_,L,L,L,_,_,_,_,_,_,_,_,
	_,_,_,_,_,_,_,L,_,_,_,_,_,_,_,
	_,_,_,_,L,L,L,L,L,L,_,_,_,_,_,
	_,_,_,_,_,L,L,L,L,L,_,_,_,_,_,
	_,_,_,_,_,_,L,L,L,_,_,_,_,_,_,
	_,_,_,_,_,_,_,_,_,_,_,_,_,_,_,

	_,_,_,_,T,T,T,T,T,T,T,_,_,_,_,
	_,_,_,_,T,T,T,T,T,T,_,_,_,_,_,
	_,_,_,_,_,T,T,T,T,T,_,_,_,_,_,
	_,_,_,_,_,T,T,T,T,T,_,_,_,_,_,
	_,_,_,_,_,t,t,t,t,t,_,_,_,_,_,
	_,_,_,_,_,t,t,t,t,t,_,_,_,_,_,
	_,_,_,_,_,t,t,t,t,t,_,_,_,_,_,
	_,_,_,_,_,t,t,t,t,t,_,_,_,_,_,
	_,_,_,_,_,t,t,t,t,t,_,_,_,_,_,
	_,_,_,_,_,_,t,t,t,_,_,_,_,_,_,
	_,_,_,_,_,_,t,t,t,_,_,_,_,_,_,
	_,_,_,_,_,_,t,t,t,_,_,_,_,_,_,
	_,_,_,_,_,_,t,t,t,_,_,_,_,_,_,
	_,_,_,_,_,_,t,t,t,_,_,_,_,_,_,
	_,_,_,_,_,_,t,t,t,_,_,_,_,_,_,
	_,_,_,_,_,_,t,t,t,_,_,_,_,_,_,
	_,_,_,_,_,_,t,t,t,_,_,_,_,_,_,
	_,_,_,_,_,_,t,t,t,_,_,_,_,_,_,
	_,_,_,_,_,_,t,t,t,_,_,_,_,_,_,
	_,_,_,_,_,_,t,t,t,_,_,_,_,_,_,
	L,L,L,L,_,_,t,t,t,_,_,_,_,_,_,
	_,_,_,_,_,_,t,t,t,_,_,_,_,_,_,
	_,_,_,_,_,_,t,t,t,_,_,_,_,_,_,
	_,_,_,_,_,_,_,t,_,_,L,L,L,L,L,
	_,_,_,_,_,_,_,t,_,_,_,L,L,L,_,
	_,_,_,_,_,_,_,t,_,_,_,_,_,_,_,
	_,_,_,_,L,L,t,t,_,_,_,_,_,_,_,
	_,_,_,_,L,_,_,t,_,_,_,_,_,_,_,
	_,_,_,_,_,_,L,t,L,_,_,_,_,_,_,
	_,_,_,_,L,L,L,L,L,L,L,_,_,_,_,
	_,_,_,_,L,L,L,L,L,L,L,_,_,_,_,
	_,_,_,_,_,L,L,L,L,L,_,_,_,_,_,
	_,_,_,_,_,_,_,L,_,_,_,_,_,_,_,

	_,_,_,_,T,T,T,T,T,T,T,_,_,_,_,
	_,_,_,_,T,T,T,T,T,T,T,_,_,_,_,
	_,_,_,_,T,T,T,T,T,T,T,_,_,_,_,
	_,_,_,_,_,T,T,T,T,T,_,_,_,_,_,
	_,_,_,_,_,t,t,t,t,t,_,_,_,_,_,
	_,_,_,_,_,t,t,t,t,t,_,_,_,_,_,
	_,_,_,_,_,t,t,t,t,t,_,_,_,_,_,
	_,_,_,_,_,t,t,t,t,t,_,_,_,_,_,
	_,_,_,_,_,t,t,t,t,t,_,_,_,_,_,
	_,_,_,_,_,t,t,t,t,t,_,_,_,_,_,
	_,_,_,_,_,t,t,t,t,t,_,_,_,_,_,
	_,_,_,_,_,_,t,t,t,_,_,_,_,_,_,
	_,_,_,_,_,_,t,t,t,_,_,_,_,_,_,
	_,_,_,_,_,_,t,t,t,t,t,t,_,_,_,
	_,_,_,_,_,_,t,t,t,_,_,L,L,L,L,
	_,_,_,_,_,_,t,t,t,_,_,_,L,L,L,
	_,_,_,_,_,_,t,t,t,_,_,_,_,_,_,
	_,_,_,_,_,_,t,t,t,_,_,_,_,_,_,
	_,_,_,_,_,_,t,t,t,_,_,_,_,_,_,
	_,_,_,t,t,t,t,t,t,_,_,_,_,_,_,
	L,L,L,L,L,_,t,t,t,_,_,_,_,_,_,
	L,L,L,L,_,_,t,t,t,_,_,_,_,_,_,
	_,_,_,_,_,_,t,t,t,t,t,t,_,_,_,
	_,_,_,_,_,_,t,t,t,_,L,t,t,t,L,
	_,_,_,_,_,_,t,t,t,_,_,L,L,L,L,
	_,_,L,L,L,L,t,t,t,_,_,_,_,_,_,
	_,_,_,_,_,_,t,t,t,_,_,_,_,_,_,
	_,_,_,_,_,_,t,t,t,_,_,_,_,_,_,
	_,_,_,_,_,L,t,t,t,L,_,_,_,_,_,
	_,_,_,_,L,L,L,t,L,L,L,_,_,_,_,
	_,_,_,_,L,L,L,L,L,L,L,_,_,_,_,
	_,_,_,_,_,L,L,L,L,L,_,_,_,_,_,
	_,_,_,_,_,_,L,L,L,_,_,_,_,_,_,

	_,_,_,_,T,T,T,T,T,T,T,_,_,_,_,
	_,_,_,_,T,T,T,T,T,T,T,_,_,_,_,
	_,_,_,_,_,T,T,T,T,T,T,_,_,_,_,
	_,_,_,_,_,T,T,T,T,T,_,_,_,_,_,
	_,_,_,_,_,t,t,t,t,t,_,_,_,_,_,
	_,_,_,_,_,t,t,t,t,t,_,_,_,_,_,
	_,_,_,_,_,t,t,t,t,t,_,_,_,_,_,
	_,_,_,_,_,t,t,t,t,t,_,_,_,_,_,
	_,_,_,_,_,t,t,t,t,t,_,_,_,_,_,
	_,_,_,_,_,_,t,t,t,_,_,_,_,_,_,
	_,_,_,_,_,_,t,t,t,_,_,_,_,_,_,
	_,_,_,_,_,_,t,t,t,_,_,_,_,_,_,
	_,_,_,_,_,_,t,t,t,_,_,_,_,_,_,
	_,_,_,_,_,_,t,t,t,_,_,t,t,_,_,
	_,_,_,_,_,_,t,t,t,_,_,L,t,t,L,
	_,_,_,_,_,_,t,t,t,_,_,_,L,L,L,
	_,_,_,_,_,_,t,t,t,_,_,_,_,_,_,
	_,_,_,_,_,_,t,t,t,_,_,_,_,_,_,
	_,_,_,_,_,_,t,t,t,_,_,_,_,_,_,
	_,_,_,t,_,_,t,t,t,_,_,_,_,_,_,
	L,t,t,t,L,_,t,t,t,_,_,_,_,_,_,
	L,L,L,L,_,_,t,t,t,_,_,_,_,_,_,
	_,_,_,_,_,_,t,t,t,_,_,_,_,_,_,
	_,_,_,_,_,_,t,t,_,_,_,L,L,L,L,
	_,_,_,_,t,t,t,t,_,_,_,L,L,L,_,
	_,L,L,L,L,L,_,t,_,_,_,_,_,_,_,
	_,_,_,L,L,_,_,t,L,L,L,L,_,_,_,
	_,_,_,_,_,_,_,t,_,_,_,_,_,_,_,
	_,_,_,_,_,_,L,t,L,_,_,_,_,_,_,
	_,_,_,_,L,L,L,L,L,L,L,_,_,_,_,
	_,_,_,_,L,L,L,L,L,L,_,_,_,_,_,
	_,_,_,_,_,_,L,L,L,_,_,_,_,_,_,
	_,_,_,_,_,_,_,L,L,_,_,_,_,_,_,

	_,_,_,_,_,T,T,T,T,T,_,_,_,_,_,
	_,_,_,_,_,T,T,T,T,T,_,_,_,_,_,
	_,_,_,_,_,t,t,t,t,t,_,_,_,_,_,
	_,_,_,_,_,_,t,t,t,_,_,_,_,_,_,
	_,_,_,_,_,_,t,t,t,_,_,_,_,_,_,
	_,_,_,_,_,_,t,t,t,_,_,_,_,_,_,
	_,_,_,_,_,_,t,t,t,_,_,_,_,_,_,
	_,_,_,_,_,_,t,t,t,_,_,_,_,_,_,
	_,_,_,_,_,_,_,t,_,_,_,_,_,_,_,
	_,_,_,_,_,_,_,t,_,_,_,_,_,_,_,
	_,_,_,_,_,_,_,t,_,_,_,_,_,_,_,
	_,_,_,_,_,_,_,_,_,_,_,_,_,_,_,
	_,_,_,_,_,_,_,_,_,_,_,_,_,_,_,
	_,_,_,_,_,_,_,_,_,_,_,_,_,_,_,
	_,_,_,_,_,_,_,_,_,_,_,L,L,L,L,
	_,_,_,_,_,_,_,_,_,_,_,_,L,L,L,
	_,_,_,_,_,_,_,_,_,_,_,_,_,_,_,
	_,_,_,_,_,_,_,_,_,_,_,_,_,_,_,
	_,_,_,_,_,_,_,t,t,_,_,_,_,_,_,
	_,_,_,_,_,_,_,L,L,L,_,_,_,_,_,
	L,L,L,L,L,_,_,_,L,_,_,_,_,_,_,
	L,L,L,L,_,_,t,_,_,_,_,_,_,_,_,
	_,_,_,_,_,_,_,_,_,_,_,_,_,_,_,
	_,_,_,_,_,_,_,_,_,_,_,L,L,L,L,
	_,_,_,_,t,_,_,_,_,_,_,_,_,_,_,
	_,L,L,t,t,L,L,t,t,t,_,_,_,_,_,
	_,_,L,L,L,_,_,L,L,t,L,L,_,_,_,
	_,_,_,_,_,_,_,_,L,L,L,_,_,_,_,
	_,_,_,_,_,_,_,L,_,_,_,_,_,_,_,
	_,_,_,_,_,L,L,L,L,L,_,_,_,_,_,
	_,_,_,_,_,L,L,L,L,L,_,_,_,_,_,
	_,_,_,_,_,_,L,_,_,_,_,_,_,_,_,
	_,_,_,_,_,_,_,_,_,_,_,_,_,_,_,

	_,_,_,_,_,T,T,T,T,T,_,_,_,_,_,
	_,_,_,_,_,_,T,T,T,_,_,_,_,_,_,
	_,_,_,_,_,_,_,T,_,_,_,_,_,_,_,
	_,_,_,_,_,_,_,_,_,_,_,_,_,_,_,
	_,_,_,_,_,_,_,_,_,_,_,_,_,_,_,
	_,_,_,_,_,_,_,_,_,_,_,_,_,_,_,
	_,_,_,_,_,_,_,_,_,_,_,_,_,_,_,
	_,_,_,_,_,_,_,_,_,_,_,_,_,_,_,
	_,_,_,_,_,_,_,_,_,_,_,_,_,_,_,
	_,_,_,_,_,_,_,_,_,_,_,_,_,_,_,
	_,_,_,_,_,_,_,_,_,_,_,_,_,_,_,
	_,_,_,_,_,_,_,_,_,_,_,_,_,_,_,
	_,_,_,_,_,_,_,_,_,_,_,_,_,_,_,
	_,_,_,_,_,_,_,_,_,_,_,_,_,_,_,
	_,_,_,_,_,_,_,_,_,_,_,L,L,L,L,
	_,_,_,_,_,_,_,_,_,_,_,_,_,_,_,
	_,_,_,_,_,_,_,_,_,_,_,_,_,_,_,
	_,_,_,_,_,_,_,_,_,_,_,_,_,_,_,
	_,_,_,_,_,_,_,_,t,_,_,_,_,_,_,
	_,_,_,_,_,_,_,L,L,L,_,_,_,_,_,
	L,L,L,L,_,_,_,_,L,L,_,_,_,_,_,
	_,_,_,_,_,_,t,_,_,_,_,_,_,_,_,
	_,_,_,_,_,L,L,L,L,_,_,_,_,_,_,
	_,_,_,_,_,_,_,_,_,_,_,_,_,_,_,
	_,_,_,_,_,_,_,_,_,_,_,_,_,_,_,
	_,L,L,L,L,L,L,_,_,_,_,_,_,_,_,
	_,_,_,L,L,_,_,L,L,t,L,L,_,_,_,
	_,_,_,_,_,_,_,_,L,L,L,_,_,_,_,
	_,_,_,_,_,_,_,_,_,_,_,_,_,_,_,
	_,_,_,_,_,_,L,L,L,_,_,_,_,_,_,
	_,_,_,_,_,_,L,L,_,_,_,_,_,_,_,
	_,_,_,_,_,_,_,_,_,_,_,_,_,_,_,
	_,_,_,_,_,_,_,_,_,_,_,_,_,_,_,

	_,_,_,_,_,_,_,_,_,_,_,_,_,_,_,
	_,_,_,_,_,_,_,_,_,_,_,_,_,_,_,
	_,_,_,_,_,_,_,_,_,_,_,_,_,_,_,
	_,_,_,_,_,_,_,_,_,_,_,_,_,_,_,
	_,_,_,_,_,_,_,_,_,_,_,_,_,_,_,
	_,_,_,_,_,_,_,_,_,_,_,_,_,_,_,
	_,_,_,_,_,_,_,_,_,_,_,_,_,_,_,
	_,_,_,_,_,_,_,_,_,_,_,_,_,_,_,
	_,_,_,_,_,_,_,_,_,_,_,_,_,_,_,
	_,_,_,_,_,_,_,_,_,_,_,_,_,_,_,
	_,_,_,_,_,_,_,_,_,_,_,_,_,_,_,
	_,_,_,_,_,_,_,_,_,_,_,_,_,_,_,
	_,_,_,_,_,_,_,_,_,_,_,_,_,_,_,
	_,_,_,_,_,_,_,_,_,_,_,_,_,_,_,
	_,_,_,_,_,_,_,_,_,_,_,_,_,_,_,
	_,_,_,_,_,_,_,_,_,_,_,_,_,_,_,
	_,_,_,_,_,_,_,_,_,_,_,_,_,_,_,
	_,_,_,_,_,_,_,_,_,_,_,_,_,_,_,
	_,_,_,_,_,_,_,_,_,_,_,_,_,_,_,
	_,_,_,_,_,_,_,L,L,L,_,_,_,_,_,
	_,_,_,_,_,_,_,_,_,_,_,_,_,_,_,
	_,_,_,_,_,_,t,_,_,_,_,_,_,_,_,
	_,_,_,_,L,L,L,L,L,_,_,_,_,_,_,
	_,_,_,_,_,_,_,_,_,_,_,_,_,_,_,
	_,_,_,_,_,_,_,_,_,_,_,_,_,_,_,
	_,_,L,L,L,L,_,_,_,_,_,_,_,_,_,
	_,_,_,_,_,_,_,L,L,L,L,L,_,_,_,
	_,_,_,_,_,_,_,_,_,L,_,_,_,_,_,
	_,_,_,_,_,_,_,_,_,_,_,_,_,_,_,
	_,_,_,_,_,_,_,L,L,_,_,_,_,_,_,
	_,_,_,_,_,_,_,_,_,_,_,_,_,_,_,
	_,_,_,_,_,_,_,_,_,_,_,_,_,_,_,
	_,_,_,_,_,_,_,_,_,_,_,_,_,_,_,

	_,_,_,_,_,_,_,_,_,_,_,_,_,_,_,
	_,_,_,_,_,_,_,_,_,_,_,_,_,_,_,
	_,_,_,_,_,_,_,_,_,_,_,_,_,_,_,
	_,_,_,_,_,_,_,_,_,_,_,_,_,_,_,
	_,_,_,_,_,_,_,_,_,_,_,_,_,_,_,
	_,_,_,_,_,_,_,_,_,_,_,_,_,_,_,
	_,_,_,_,_,_,_,_,_,_,_,_,_,_,_,
	_,_,_,_,_,_,_,_,_,_,_,_,_,_,_,
	_,_,_,_,_,_,_,_,_,_,_,_,_,_,_,
	_,_,_,_,_,_,_,_,_,_,_,_,_,_,_,
	_,_,_,_,_,_,_,_,_,_,_,_,_,_,_,
	_,_,_,_,_,_,_,_,_,_,_,_,_,_,_,
	_,_,_,_,_,_,_,_,_,_,_,_,_,_,_,
	_,_,_,_,_,_,_,_,_,_,_,_,_,_,_,
	_,_,_,_,_,_,_,_,_,_,_,_,_,_,_,
	_,_,_,_,_,_,_,_,_,_,_,_,_,_,_,
	_,_,_,_,_,_,_,_,_,_,_,_,_,_,_,
	_,_,_,_,_,_,_,_,_,_,_,_,_,_,_,
	_,_,_,_,_,_,_,_,_,_,_,_,_,_,_,
	_,_,_,_,_,_,_,_,_,_,_,_,_,_,_,
	_,_,_,_,_,_,_,_,_,_,_,_,_,_,_,
	_,_,_,_,_,_,t,_,_,_,_,_,_,_,_,
	_,_,_,_,L,L,t,L,L,_,_,_,_,_,_,
	_,_,_,_,_,L,L,L,_,_,_,_,_,_,_,
	_,_,_,_,_,_,_,_,_,_,_,_,_,_,_,
	_,_,_,_,_,_,_,_,_,_,_,_,_,_,_,
	_,_,_,_,_,_,_,_,L,L,L,_,_,_,_,
	_,_,_,_,_,_,_,_,_,_,_,_,_,_,_,
	_,_,_,_,_,_,_,_,_,_,_,_,_,_,_,
	_,_,_,_,_,_,_,_,_,_,_,_,_,_,_,
	_,_,_,_,_,_,_,_,_,_,_,_,_,_,_,
	_,_,_,_,_,_,_,_,_,_,_,_,_,_,_,
	_,_,_,_,_,_,_,_,_,_,_,_,_,_,_,

	_,_,_,_,_,_,_,_,_,_,_,_,_,_,_,
	_,_,_,_,_,_,_,_,_,_,_,_,_,_,_,
	_,_,_,_,_,_,_,_,_,_,_,_,_,_,_,
	_,_,_,_,_,_,_,_,_,_,_,_,_,_,_,
	_,_,_,_,_,_,_,_,_,_,_,_,_,_,_,
	_,_,_,_,_,_,_,_,_,_,_,_,_,_,_,
	_,_,_,_,_,_,_,_,_,_,_,_,_,_,_,
	_,_,_,_,_,_,_,_,_,_,_,_,_,_,_,
	_,_,_,_,_,_,_,_,_,_,_,_,_,_,_,
	_,_,_,_,_,_,_,_,_,_,_,_,_,_,_,
	_,_,_,_,_,_,_,_,_,_,_,_,_,_,_,
	_,_,_,_,_,_,_,_,_,_,_,_,_,_,_,
	_,_,_,_,_,_,_,_,_,_,_,_,_,_,_,
	_,_,_,_,_,_,_,_,_,_,_,_,_,_,_,
	_,_,_,_,_,_,_,_,_,_,_,_,_,_,_,
	_,_,_,_,_,_,_,_,_,_,_,_,_,_,_,
	_,_,_,_,_,_,_,_,_,_,_,_,_,_,_,
	_,_,_,_,_,_,_,_,_,_,_,_,_,_,_,
	_,_,_,_,_,_,_,_,_,_,_,_,_,_,_,
	_,_,_,_,_,_,_,_,_,_,_,_,_,_,_,
	_,_,_,_,_,_,_,_,_,_,_,_,_,_,_,
	_,_,_,_,_,_,_,_,_,_,_,_,_,_,_,
	_,_,_,_,L,L,t,L,L,_,_,_,_,_,_,
	_,_,_,_,_,L,L,L,_,_,_,_,_,_,_,
	_,_,_,_,_,_,_,_,_,_,_,_,_,_,_,
	_,_,_,_,_,_,_,_,_,_,_,_,_,_,_,
	_,_,_,_,_,_,_,_,_,_,_,_,_,_,_,
	_,_,_,_,_,_,_,_,_,_,_,_,_,_,_,
	_,_,_,_,_,_,_,_,_,_,_,_,_,_,_,
	_,_,_,_,_,_,_,_,_,_,_,_,_,_,_,
	_,_,_,_,_,_,_,_,_,_,_,_,_,_,_,
	_,_,_,_,_,_,_,_,_,_,_,_,_,_,_,
	_,_,_,_,_,_,_,_,_,_,_,_,_,_,_,

	_,_,_,_,_,_,_,_,_,_,_,_,_,_,_,
	_,_,_,_,_,_,_,_,_,_,_,_,_,_,_,
	_,_,_,_,_,_,_,_,_,_,_,_,_,_,_,
	_,_,_,_,_,_,_,_,_,_,_,_,_,_,_,
	_,_,_,_,_,_,_,_,_,_,_,_,_,_,_,
	_,_,_,_,_,_,_,_,_,_,_,_,_,_,_,
	_,_,_,_,_,_,_,_,_,_,_,_,_,_,_,
	_,_,_,_,_,_,_,_,_,_,_,_,_,_,_,
	_,_,_,_,_,_,_,_,_,_,_,_,_,_,_,
	_,_,_,_,_,_,_,_,_,_,_,_,_,_,_,
	_,_,_,_,_,_,_,_,_,_,_,_,_,_,_,
	_,_,_,_,_,_,_,_,_,_,_,_,_,_,_,
	_,_,_,_,_,_,_,_,_,_,_,_,_,_,_,
	_,_,_,_,_,_,_,_,_,_,_,_,_,_,_,
	_,_,_,_,_,_,_,_,_,_,_,_,_,_,_,
	_,_,_,_,_,_,_,_,_,_,_,_,_,_,_,
	_,_,_,_,_,_,_,_,_,_,_,_,_,_,_,
	_,_,_,_,_,_,_,_,_,_,_,_,_,_,_,
	_,_,_,_,_,_,_,_,_,_,_,_,_,_,_,
	_,_,_,_,_,_,_,_,_,_,_,_,_,_,_,
	_,_,_,_,_,_,_,_,_,_,_,_,_,_,_,
	_,_,_,_,_,_,_,_,_,_,_,_,_,_,_,
	_,_,_,_,L,L,L,L,L,_,_,_,_,_,_,
	_,_,_,_,_,_,L,_,_,_,_,_,_,_,_,
	_,_,_,_,_,_,_,_,_,_,_,_,_,_,_,
	_,_,_,_,_,_,_,_,_,_,_,_,_,_,_,
	_,_,_,_,_,_,_,_,_,_,_,_,_,_,_,
	_,_,_,_,_,_,_,_,_,_,_,_,_,_,_,
	_,_,_,_,_,_,_,_,_,_,_,_,_,_,_,
	_,_,_,_,_,_,_,_,_,_,_,_,_,_,_,
	_,_,_,_,_,_,_,_,_,_,_,_,_,_,_,
	_,_,_,_,_,_,_,_,_,_,_,_,_,_,_,
	_,_,_,_,_,_,_,_,_,_,_,_,_,_,_,

	}
}
