
local _ = {name = "air", prob = 0}
local t = {name = "ethereal:redwood_trunk", prob = 255}
local T = {name = "ethereal:redwood_trunk", prob = 255, force_place = true}
local L = {name = "ethereal:redwood_leaves", prob = 255}

ethereal.redwood_small_tree = {

	size = {x = 9, y = 21, z = 9},

	yslice_prob = {
		{ypos = 2, prob = 127},
		{ypos = 3, prob = 127},
		{ypos = 4, prob = 127},
		{ypos = 5, prob = 127},
		{ypos = 7, prob = 127}
	},

	data = {

	_,_,_,_,_,_,_,_,_,
	_,_,_,_,_,_,_,_,_,
	_,_,_,_,_,_,_,_,_,
	_,_,_,_,_,_,_,_,_,
	_,_,_,_,_,_,_,_,_,
	_,_,_,_,_,_,_,_,_,
	_,_,_,_,_,_,_,_,_,
	_,_,_,_,_,_,_,_,_,
	_,_,_,_,_,_,_,_,_,
	_,_,_,_,_,_,_,_,_,
	_,_,_,_,_,_,_,_,_,
	_,_,_,_,L,L,t,L,L,
	_,_,_,_,_,L,L,L,_,
	_,_,_,_,_,_,_,_,_,
	_,L,L,L,L,_,_,_,_,
	_,_,_,_,_,_,_,_,_,
	_,_,_,_,_,_,_,_,_,
	_,_,_,L,L,_,_,_,_,
	_,_,_,_,_,_,_,_,_,
	_,_,_,_,_,_,_,_,_,
	_,_,_,_,_,_,_,_,_,

	_,_,_,_,_,_,_,_,_,
	_,_,_,_,_,_,_,_,_,
	_,_,_,_,_,_,_,_,_,
	_,_,_,_,_,_,_,_,_,
	_,_,_,_,_,_,_,_,_,
	_,_,_,_,_,_,_,_,_,
	_,_,_,_,_,_,_,_,_,
	_,_,_,_,_,_,_,_,_,
	_,_,_,_,_,_,_,_,_,
	_,_,_,_,_,_,_,_,_,
	_,_,_,_,_,_,t,_,_,
	_,_,_,_,L,L,t,L,L,
	_,_,_,_,_,L,L,L,_,
	_,_,_,_,_,_,_,_,_,
	L,L,L,L,L,L,_,_,_,
	_,_,L,L,_,_,_,_,_,
	_,_,_,_,_,_,_,_,_,
	_,_,_,L,L,L,L,_,_,
	_,_,_,L,L,L,_,_,_,
	_,_,_,_,_,_,_,_,_,
	_,_,_,_,_,_,_,_,_,

	_,_,_,_,_,_,_,_,_,
	_,_,_,_,_,_,_,_,_,
	_,_,_,_,_,_,_,_,_,
	_,_,_,_,_,_,_,_,_,
	_,_,_,_,_,_,_,_,_,
	_,_,_,_,_,_,_,_,_,
	_,_,_,_,_,_,_,_,_,
	_,_,_,_,_,_,_,_,_,
	_,_,_,_,_,_,_,_,_,
	_,_,_,_,_,_,_,_,_,
	_,_,_,_,_,t,t,_,_,
	_,_,_,_,_,L,L,_,L,
	_,_,_,_,_,_,_,_,_,
	_,_,_,_,_,_,_,_,_,
	L,L,t,t,L,L,_,_,_,
	_,L,L,L,_,_,_,_,_,
	_,_,_,_,L,_,_,_,_,
	_,L,L,L,L,L,L,_,_,
	_,_,L,L,L,L,L,_,_,
	_,_,_,L,L,L,_,_,_,
	_,_,_,_,_,_,_,_,_,

	_,_,_,T,T,T,_,_,_,
	_,_,_,T,T,T,_,_,_,
	_,_,_,T,T,T,_,_,_,
	_,_,_,T,T,T,_,_,_,
	_,_,_,t,t,t,_,_,_,
	_,_,_,t,t,t,_,_,_,
	_,_,_,t,t,t,_,_,_,
	_,_,_,t,t,t,_,_,_,
	_,_,_,_,t,_,_,_,_,
	_,_,_,_,t,_,_,_,_,
	_,_,_,_,t,_,_,_,_,
	_,_,_,_,t,_,_,L,L,
	_,_,_,_,t,_,_,_,L,
	_,_,_,_,t,_,_,_,_,
	_,L,L,t,t,_,_,_,_,
	_,L,_,_,t,_,_,_,_,
	_,_,_,L,t,L,_,_,_,
	_,L,L,L,L,L,L,L,_,
	_,L,L,L,L,L,L,L,_,
	_,_,L,L,L,L,L,_,_,
	_,_,_,_,L,_,_,_,_,

	_,_,_,T,T,T,_,_,_,
	_,_,_,T,T,T,_,_,_,
	_,_,_,T,T,T,_,_,_,
	_,_,_,T,T,T,_,_,_,
	_,_,_,t,t,t,_,_,_,
	_,_,_,t,t,t,_,_,_,
	_,_,_,t,t,t,_,_,_,
	_,_,_,_,t,_,_,_,_,
	_,_,_,_,t,_,_,_,_,
	_,_,_,_,t,_,_,_,_,
	_,_,_,t,t,t,t,t,t,
	_,_,_,t,t,t,_,L,t,
	_,_,_,t,t,t,_,_,L,
	L,L,L,t,t,t,_,_,_,
	_,_,_,t,t,t,_,_,_,
	_,_,_,t,t,t,_,_,_,
	_,_,L,t,t,t,L,_,_,
	_,L,L,L,t,L,L,L,_,
	_,L,L,L,L,L,L,L,_,
	_,_,L,L,L,L,L,_,_,
	_,_,_,L,L,L,_,_,_,

	_,_,_,T,T,T,_,_,_,
	_,_,_,T,T,T,_,_,_,
	_,_,_,T,T,T,_,_,_,
	_,_,_,T,T,T,_,_,_,
	_,_,_,t,t,t,_,_,_,
	_,_,_,t,t,t,_,_,_,
	_,_,_,t,t,t,_,_,_,
	_,_,_,_,t,_,_,_,_,
	_,_,_,_,t,_,_,_,_,
	_,_,_,_,t,_,_,_,_,
	_,_,_,t,t,t,_,_,_,
	_,_,_,t,t,_,_,_,L,
	_,t,t,t,t,_,_,_,L,
	L,L,L,_,t,_,_,_,_,
	L,L,_,_,t,L,L,L,L,
	_,_,_,_,t,_,_,_,_,
	_,_,_,L,t,L,_,_,_,
	_,L,L,L,L,L,L,L,_,
	_,L,L,L,L,L,L,_,_,
	_,_,_,L,L,L,_,_,_,
	_,_,_,_,L,L,_,_,_,

	_,_,_,_,_,_,_,_,_,
	_,_,_,_,_,_,_,_,_,
	_,_,_,_,_,_,_,_,_,
	_,_,_,_,_,_,_,_,_,
	_,_,_,_,_,_,_,_,_,
	_,_,_,_,_,_,_,_,_,
	_,_,_,_,_,_,_,_,_,
	_,_,_,_,_,_,_,_,_,
	_,_,_,_,_,_,_,_,_,
	_,_,_,_,_,_,_,_,_,
	_,_,_,_,_,_,_,_,_,
	_,_,_,_,_,_,_,_,_,
	_,t,_,_,_,_,_,_,_,
	t,t,L,L,t,t,t,_,_,
	L,L,_,_,L,L,t,L,L,
	_,_,_,_,_,L,L,L,_,
	_,_,_,_,L,_,_,_,_,
	_,_,L,L,L,L,L,_,_,
	_,_,L,L,L,L,L,_,_,
	_,_,_,L,_,_,_,_,_,
	_,_,_,_,_,_,_,_,_,

	_,_,_,_,_,_,_,_,_,
	_,_,_,_,_,_,_,_,_,
	_,_,_,_,_,_,_,_,_,
	_,_,_,_,_,_,_,_,_,
	_,_,_,_,_,_,_,_,_,
	_,_,_,_,_,_,_,_,_,
	_,_,_,_,_,_,_,_,_,
	_,_,_,_,_,_,_,_,_,
	_,_,_,_,_,_,_,_,_,
	_,_,_,_,_,_,_,_,_,
	_,_,_,_,_,_,_,_,_,
	_,_,_,_,_,_,_,_,_,
	_,_,_,_,_,_,_,_,_,
	L,L,L,L,_,_,_,_,_,
	L,L,_,_,L,L,t,L,L,
	_,_,_,_,_,L,L,L,_,
	_,_,_,_,_,_,_,_,_,
	_,_,_,L,L,L,_,_,_,
	_,_,_,L,L,_,_,_,_,
	_,_,_,_,_,_,_,_,_,
	_,_,_,_,_,_,_,_,_,

	_,_,_,_,_,_,_,_,_,
	_,_,_,_,_,_,_,_,_,
	_,_,_,_,_,_,_,_,_,
	_,_,_,_,_,_,_,_,_,
	_,_,_,_,_,_,_,_,_,
	_,_,_,_,_,_,_,_,_,
	_,_,_,_,_,_,_,_,_,
	_,_,_,_,_,_,_,_,_,
	_,_,_,_,_,_,_,_,_,
	_,_,_,_,_,_,_,_,_,
	_,_,_,_,_,_,_,_,_,
	_,_,_,_,_,_,_,_,_,
	_,_,_,_,_,_,_,_,_,
	L,L,L,_,_,_,_,_,_,
	_,_,_,_,L,L,L,L,L,
	_,_,_,_,_,_,L,_,_,
	_,_,_,_,_,_,_,_,_,
	_,_,_,_,L,L,_,_,_,
	_,_,_,_,_,_,_,_,_,
	_,_,_,_,_,_,_,_,_,
	_,_,_,_,_,_,_,_,_,

	}
}
